Workbook

Sheet Daily Plan
A1: Chapter 5 Learning Plan (Resnick: A Probability Path)
A2: Start Date (edit) | B2: 46053 | D2: Status Legend | E2: Not Started / In Progress / Done
A4: Day | B4: Date | C4: Section | D4: Reading (if any) | E4: Tasks (exercise + level) | F4: Est. minutes | G4: Status | H4: C1 Due (auto) | I4: C1 Done? | J4: Notes | K4: Link/Ref
A5: 1 | B5: =IF($B$2="","",$B$2+A5-1) -> 46053 | C5: 5.1–5.2.3 | E5: Exercises: Ex2 (L2), Ex4 (L2) | F5: 75 | G5: Done | H5: =IF(G5="Done",B5+2,"") -> 46055 | I5: Yes | J5: Actual done: 2026-01-31
A6: 2 | B6: =IF($B$2="","",$B$2+A6-1) -> 46054 | C6: 5.1–5.2.3 | E6: Exercises: Ex1 (L2) | F6: 60 | G6: Done | H6: =IF(G6="Done",B6+2,"") -> 46056 | I6: Yes | J6: Actual done: 2026-01-31
A7: 3 | B7: =IF($B$2="","",$B$2+A7-1) -> 46055 | C7: 5.1–5.2.3 | E7: Exercises: Ex3 (L2) | F7: 60 | G7: Done | H7: =IF(G7="Done",B7+2,"") -> 46057 | I7: Yes | J7: Actual done: 2026-02-01
A8: 4 | B8: =IF($B$2="","",$B$2+A8-1) -> 46056 | C8: 5.1–5.2.3 | E8: Exercises: Ex5(a) (L2) | F8: 60 | G8: Done | H8: =IF(G8="Done",B8+2,"") -> 46058 | I8: Yes | J8: Actual done: 2026-02-02
A9: 5 | B9: =IF($B$2="","",$B$2+A9-1) -> 46057 | C9: 5.1–5.2.3 | E9: Exercises: Ex5(b–d) (L2) | F9: 75 | G9: Done | H9: =IF(G9="Done",B9+2,"") -> 46059 | I9: Yes | J9: Actual done: 2026-02-03
A10: 6 | B10: =IF($B$2="","",$B$2+A10-1) -> 46058 | C10: 5.1–5.2.3 | E10: Exercises: Ex6(a–c) (L1) | F10: 90 | G10: Done | H10: =IF(G10="Done",B10+2,"") -> 46060 | J10: (a)(b): 2026-02-04, © 2026-02-05
A11: 7 | B11: =IF($B$2="","",$B$2+A11-1) -> 46059 | C11: 5.1–5.2.3 | E11: Exercises: Ex10 (L1) + 10-min recap note | F11: 60 | G11: Done | H11: =IF(G11="Done",B11+2,"") -> 46061 | J11: Actual done: 2026-02-05
A12: 8 | B12: =IF($B$2="","",$B$2+A12-1) -> 46060 | C12: 5.3 | D12: Read §5.3 (first half) | E12: Exercises: Ex38 (L2) | F12: 75 | G12: Done | H12: =IF(G12="Done",B12+2,"") -> 46062 | J12: Actual done: 2026-02-06
A13: 9 | B13: =IF($B$2="","",$B$2+A13-1) -> 46061 | C13: 5.3 | D13: Read §5.3 (second half) | E13: Exercises: Ex7 (L2) | F13: 75 | G13: Done | H13: =IF(G13="Done",B13+2,"") -> 46063 | J13: Actual done: 2026-02-06
A14: 10 | B14: =IF($B$2="","",$B$2+A14-1) -> 46062 | C14: 5.3 | E14: Exercises: Ex8(a–b) (L3) | F14: 60 | G14: Done | H14: =IF(G14="Done",B14+2,"") -> 46064 | J14: Actual done: 2026-02-08
A15: 11 | B15: =IF($B$2="","",$B$2+A15-1) -> 46063 | C15: 5.3 | E15: Exercises: Ex13 (L1) | F15: 90 | G15: Done | H15: =IF(G15="Done",B15+2,"") -> 46065 | I15: Yes | J15: Actual done: 2026-02-09
A16: 12 | B16: =IF($B$2="","",$B$2+A16-1) -> 46064 | C16: 5.3 | E16: Exercises: Ex30 (L1) | F16: 90 | G16: Done | H16: =IF(G16="Done",B16+2,"") -> 46066 | I16: Yes | J16: Actual done: 2026-02-10
A17: 13 | B17: =IF($B$2="","",$B$2+A17-1) -> 46065 | C17: 5.3 | E17: Exercises: Ex36 (L1) | F17: 90 | G17: Done | H17: =IF(G17="Done",B17+2,"") -> 46067 | J17: Actual done: 2026-02-11
A18: 14 | B18: =IF($B$2="","",$B$2+A18-1) -> 46066 | C18: 5.3 | E18: Exercises: Ex15(a–b) (L3) + quick §5.3 review | F18: 45 | G18: Done | H18: =IF(G18="Done",B18+2,"") -> 46068 | J18: Actual done: 2026-02-12
A19: 15 | B19: =IF($B$2="","",$B$2+A19-1) -> 46067 | C19: 5.4 | D19: Read §5.4 | E19: Exercises: Ex6(d) (L1) | F19: 75 | G19: Done | H19: =IF(G19="Done",B19+2,"") -> 46069 | J19: Read 5.4 at 2026-02-10
A20: 16 | B20: =IF($B$2="","",$B$2+A20-1) -> 46068 | C20: 5.4 | E20: Exercises: Ex6(e) (L1) (finish Ex6) | F20: 60 | G20: Done | H20: =IF(G20="Done",B20+2,"") -> 46070 | J20: Actual done: 2026-02-13
A21: 17 | B21: =IF($B$2="","",$B$2+A21-1) -> 46069 | C21: 5.5 | D21: Read §5.5 | E21: Exercises: Ex14 (L2) | F21: 75 | G21: Done | H21: =IF(G21="Done",B21+2,"") -> 46071 | J21: Read 5.5 at 2026-02-12 Actual done: 2026-02-13
A22: 18 | B22: =IF($B$2="","",$B$2+A22-1) -> 46070 | C22: 5.5 | E22: Exercises: Ex20(a) (L1) | F22: 90 | G22: Done | H22: =IF(G22="Done",B22+2,"") -> 46072 | J22: Actual done: 2026-02-14
A23: 19 | B23: =IF($B$2="","",$B$2+A23-1) -> 46071 | C23: 5.5 | E23: Exercises: Ex20(b) (L1) | F23: 90 | G23: Done | H23: =IF(G23="Done",B23+2,"") -> 46073 | J23: Actual done: 2026-02-15
A24: 20 | B24: =IF($B$2="","",$B$2+A24-1) -> 46072 | C24: 5.5 | E24: Exercises: Ex20(c–e) (L1) (finish Ex20) | F24: 90 | G24: Done | H24: =IF(G24="Done",B24+2,"") -> 46074 | J24: Actual done: 2026-02-16
A25: 21 | B25: =IF($B$2="","",$B$2+A25-1) -> 46073 | C25: 5.3/5.5 | E25: Exercises: Ex21 (L2) | F25: 60 | G25: Done | H25: =IF(G25="Done",B25+2,"") -> 46075 | J25: Actual done: 2026-02-18
A26: 22 | B26: =IF($B$2="","",$B$2+A26-1) -> 46074 | C26: 5.6 | D26: Read §5.6 | E26: Exercises: Ex16(a) (L2) | F26: 75 | G26: Done | H26: =IF(G26="Done",B26+2,"") -> 46076 | J26: Actual done: 2026-02-22
A27: 23 | B27: =IF($B$2="","",$B$2+A27-1) -> 46075 | C27: 5.6 | E27: Exercises: Ex18 (L3) | F27: 45 | G27: Done | H27: =IF(G27="Done",B27+2,"") -> 46077 | J27: Actual done: 2026-02-25
A28: 24 | B28: =IF($B$2="","",$B$2+A28-1) -> 46076 | C28: 5.7 | D28: Read §5.7 | E28: Exercises: Ex23 (L2) | F28: 75 | G28: Done | H28: =IF(G28="Done",B28+2,"") -> 46078 | J28: Actual done: 2026-03-01
A29: 25 | B29: =IF($B$2="","",$B$2+A29-1) -> 46077 | C29: 5.7 | E29: Exercises: Ex12 (L1) (part 1) | F29: 90 | G29: Done | H29: =IF(G29="Done",B29+2,"") -> 46079
A30: 26 | B30: =IF($B$2="","",$B$2+A30-1) -> 46078 | C30: 5.7 | E30: Exercises: Ex12 (L1) (part 2) (finish Ex12) | F30: 90 | G30: Done | H30: =IF(G30="Done",B30+2,"") -> 46080 | J30: Actual done: 2026-03-04
A31: 27 | B31: =IF($B$2="","",$B$2+A31-1) -> 46079 | C31: 5.9 | E31: Exercises: Ex17 (L2) | F31: 75 | G31: Done | H31: =IF(G31="Done",B31+2,"") -> 46081 | J31: Actual done: 2026-03-06
A32: 28 | B32: =IF($B$2="","",$B$2+A32-1) -> 46080 | C32: misc | E32: Exercises: Ex27 (L3) | F32: 45 | G32: Done | H32: =IF(G32="Done",B32+2,"") -> 46082 | J32: Actual done: 2026-03-08
A33: 29 | B33: =IF($B$2="","",$B$2+A33-1) -> 46081 | C33: 5.8 | D33: Read §5.8 | E33: Exercises: Ex16(b) (L2) | F33: 75 | G33: Done | H33: =IF(G33="Done",B33+2,"") -> 46083 | J33: Actual done: 2026-03-09
A34: 30 | B34: =IF($B$2="","",$B$2+A34-1) -> 46082 | C34: 5.8 | E34: Exercises: Ex16(c) (L2) | F34: 75 | G34: Done | H34: =IF(G34="Done",B34+2,"") -> 46084 | J34: Actual done: 2026-03-10
A35: 31 | B35: =IF($B$2="","",$B$2+A35-1) -> 46083 | C35: 5.4/5.8 | E35: Exercises: Ex11 (L2) | F35: 60 | G35: Done | H35: =IF(G35="Done",B35+2,"") -> 46085 | J35: Actual done: 2026-03-11
A36: 32 | B36: =IF($B$2="","",$B$2+A36-1) -> 46084 | C36: 5.9 | E36: Exercises: Ex19 (L1) | F36: 90 | G36: Done | H36: =IF(G36="Done",B36+2,"") -> 46086 | J36: Actual done: 2026-03-12
A37: 33 | B37: =IF($B$2="","",$B$2+A37-1) -> 46085 | C37: 5.9 | D37: Read §5.9 (part 1) | E37: Exercises: Ex22(a) (L1) | F37: 90 | G37: Done | H37: =IF(G37="Done",B37+2,"") -> 46087 | J37: Actual done: 2026-03-12
A38: 34 | B38: =IF($B$2="","",$B$2+A38-1) -> 46086 | C38: 5.9 | D38: Read §5.9 (part 2) | E38: Exercises: Ex22(b) (L1) | F38: 90 | G38: Done | H38: =IF(G38="Done",B38+2,"") -> 46088 | J38: Actual done: 2026-03-12
A39: 35 | B39: =IF($B$2="","",$B$2+A39-1) -> 46087 | C39: 5.9 | E39: Exercises: Ex22(c) (L1) | F39: 60 | G39: Done | H39: =IF(G39="Done",B39+2,"") -> 46089 | J39: Actual done: 2026-03-12
A40: 36 | B40: =IF($B$2="","",$B$2+A40-1) -> 46088 | C40: 5.9 | E40: Exercises: Ex22(d–f) (L1) (finish Ex22) | F40: 90 | G40: Done | H40: =IF(G40="Done",B40+2,"") -> 46090 | J40: Actual done: 2026-03-13
A41: 37 | B41: =IF($B$2="","",$B$2+A41-1) -> 46089 | C41: 5.3 | E41: Exercises: Ex24 (L2) | F41: 60 | G41: Done | H41: =IF(G41="Done",B41+2,"") -> 46091 | J41: Actual done: 2026-03-13
...

Sheet Exercise Map
A1: Exercise Map (all Chapter 5 exercises included)
A2: Start Date (linked) | B2: ='Daily Plan'!B2 -> 46053
A3: Exercise | B3: Level | C3: Planned Day(s) | D3: Planned Date(s) | E3: Section(s) | F3: Notes
A4: 1 | B4: L2 | C4: 2 | D4: =IF($B$2="","",TEXT($B$2+2-1,"yyyy-mm-dd")) -> 2026-02-01 | E4: 5.1–5.2.3
A5: 2 | B5: L2 | C5: 1 | D5: =IF($B$2="","",TEXT($B$2+1-1,"yyyy-mm-dd")) -> 2026-01-31 | E5: 5.1–5.2.3
A6: 3 | B6: L2 | C6: 3 | D6: =IF($B$2="","",TEXT($B$2+3-1,"yyyy-mm-dd")) -> 2026-02-02 | E6: 5.1–5.2.3
A7: 4 | B7: L2 | C7: 1 | D7: =IF($B$2="","",TEXT($B$2+1-1,"yyyy-mm-dd")) -> 2026-01-31 | E7: 5.1–5.2.3
A8: 5 | B8: L2 | C8: 4–5 | D8: =IF($B$2="","",TEXT($B$2+4-1,"yyyy-mm-dd")&" – "&TEXT($B$2+5-1,"yyyy-mm-dd")) -> 2026-02-03 – 2026-02-04 | E8: 5.1–5.2.3
A9: 6 | B9: L2 | C9: 6–16 | D9: =IF($B$2="","",TEXT($B$2+6-1,"yyyy-mm-dd")&" – "&TEXT($B$2+16-1,"yyyy-mm-dd")) -> 2026-02-05 – 2026-02-15 | E9: 5.1–5.2.3, 5.4
A10: 7 | B10: L2 | C10: 9 | D10: =IF($B$2="","",TEXT($B$2+9-1,"yyyy-mm-dd")) -> 2026-02-08 | E10: 5.3
A11: 8 | B11: L2 | C11: 10 | D11: =IF($B$2="","",TEXT($B$2+10-1,"yyyy-mm-dd")) -> 2026-02-09 | E11: 5.3
A12: 9 | B12: L2 | C12: 48 | D12: =IF($B$2="","",TEXT($B$2+48-1,"yyyy-mm-dd")) -> 2026-03-19 | E12: 5.9
A13: 10 | B13: L1 | C13: 7 | D13: =IF($B$2="","",TEXT($B$2+7-1,"yyyy-mm-dd")) -> 2026-02-06 | E13: 5.1–5.2.3
A14: 11 | B14: L2 | C14: 31 | D14: =IF($B$2="","",TEXT($B$2+31-1,"yyyy-mm-dd")) -> 2026-03-02 | E14: 5.4/5.8
A15: 12 | B15: L1 | C15: 25–26 | D15: =IF($B$2="","",TEXT($B$2+25-1,"yyyy-mm-dd")&" – "&TEXT($B$2+26-1,"yyyy-mm-dd")) -> 2026-02-24 – 2026-02-25 | E15: 5.7
A16: 13 | B16: L1 | C16: 11 | D16: =IF($B$2="","",TEXT($B$2+11-1,"yyyy-mm-dd")) -> 2026-02-10 | E16: 5.3
A17: 14 | B17: L2 | C17: 17 | D17: =IF($B$2="","",TEXT($B$2+17-1,"yyyy-mm-dd")) -> 2026-02-16 | E17: 5.5
A18: 15 | B18: L2 | C18: 14 | D18: =IF($B$2="","",TEXT($B$2+14-1,"yyyy-mm-dd")) -> 2026-02-13 | E18: 5.3
A19: 16 | B19: L2 | C19: 22–30 | D19: =IF($B$2="","",TEXT($B$2+22-1,"yyyy-mm-dd")&" – "&TEXT($B$2+30-1,"yyyy-mm-dd")) -> 2026-02-21 – 2026-03-01 | E19: 5.6, 5.8
A20: 17 | B20: L2 | C20: 27 | D20: =IF($B$2="","",TEXT($B$2+27-1,"yyyy-mm-dd")) -> 2026-02-26 | E20: 5.9
A21: 18 | B21: L3 | C21: 23 | D21: =IF($B$2="","",TEXT($B$2+23-1,"yyyy-mm-dd")) -> 2026-02-22 | E21: 5.6
A22: 19 | B22: L1 | C22: 32 | D22: =IF($B$2="","",TEXT($B$2+32-1,"yyyy-mm-dd")) -> 2026-03-03 | E22: 5.9
A23: 20 | B23: L2 | C23: 18–20 | D23: =IF($B$2="","",TEXT($B$2+18-1,"yyyy-mm-dd")&" – "&TEXT($B$2+20-1,"yyyy-mm-dd")) -> 2026-02-17 – 2026-02-19 | E23: 5.5
A24: 21 | B24: L2 | C24: 21 | D24: =IF($B$2="","",TEXT($B$2+21-1,"yyyy-mm-dd")) -> 2026-02-20 | E24: 5.3/5.5
A25: 22 | B25: L2 | C25: 33–36 | D25: =IF($B$2="","",TEXT($B$2+33-1,"yyyy-mm-dd")&" – "&TEXT($B$2+36-1,"yyyy-mm-dd")) -> 2026-03-04 – 2026-03-07 | E25: 5.9
A26: 23 | B26: L2 | C26: 24 | D26: =IF($B$2="","",TEXT($B$2+24-1,"yyyy-mm-dd")) -> 2026-02-23 | E26: 5.7
A27: 24 | B27: L2 | C27: 37 | D27: =IF($B$2="","",TEXT($B$2+37-1,"yyyy-mm-dd")) -> 2026-03-08 | E27: 5.3
A28: 25 | B28: L3 | C28: 45–46 | D28: =IF($B$2="","",TEXT($B$2+45-1,"yyyy-mm-dd")&" – "&TEXT($B$2+46-1,"yyyy-mm-dd")) -> 2026-03-16 – 2026-03-17 | E28: misc
A29: 26 | B29: L2 | C29: 40 | D29: =IF($B$2="","",TEXT($B$2+40-1,"yyyy-mm-dd")) -> 2026-03-11 | E29: misc
A30: 27 | B30: L3 | C30: 28 | D30: =IF($B$2="","",TEXT($B$2+28-1,"yyyy-mm-dd")) -> 2026-02-27 | E30: misc
A31: 28 | B31: L2 | C31: 39 | D31: =IF($B$2="","",TEXT($B$2+39-1,"yyyy-mm-dd")) -> 2026-03-10 | E31: 5.3
A32: 29 | B32: L2 | C32: 41 | D32: =IF($B$2="","",TEXT($B$2+41-1,"yyyy-mm-dd")) -> 2026-03-12 | E32: 5.3
A33: 30 | B33: L1 | C33: 12 | D33: =IF($B$2="","",TEXT($B$2+12-1,"yyyy-mm-dd")) -> 2026-02-11 | E33: 5.3
A34: 31 | B34: L2 | C34: 43–44 | D34: =IF($B$2="","",TEXT($B$2+43-1,"yyyy-mm-dd")&" – "&TEXT($B$2+44-1,"yyyy-mm-dd")) -> 2026-03-14 – 2026-03-15 | E34: wrap
A35: 32 | B35: L2 | C35: 42 | D35: =IF($B$2="","",TEXT($B$2+42-1,"yyyy-mm-dd")) -> 2026-03-13 | E35: wrap
A36: 33 | B36: L2 | C36: 42 | D36: =IF($B$2="","",TEXT($B$2+42-1,"yyyy-mm-dd")) -> 2026-03-13 | E36: wrap
A37: 34 | B37: L2 | C37: 42 | D37: =IF($B$2="","",TEXT($B$2+42-1,"yyyy-mm-dd")) -> 2026-03-13 | E37: wrap
A38: 35 | B38: L2 | C38: 38 | D38: =IF($B$2="","",TEXT($B$2+38-1,"yyyy-mm-dd")) -> 2026-03-09 | E38: 5.9
A39: 36 | B39: L1 | C39: 13 | D39: =IF($B$2="","",TEXT($B$2+13-1,"yyyy-mm-dd")) -> 2026-02-12 | E39: 5.3
A40: 37 | B40: L1 | C40: 47 | D40: =IF($B$2="","",TEXT($B$2+47-1,"yyyy-mm-dd")) -> 2026-03-18 | E40: 5.1–5.2.3
...

Sheet Progress
A1: Progress Dashboard
A3: Start Date | B3: ='Daily Plan'!B2 -> 46053
A5: Days Planned | B5: 52
A6: Days Done | B6: =COUNTIF('Daily Plan'!G5:G56,"Done") -> 52
A7: Days In Progress | B7: =COUNTIF('Daily Plan'!G5:G56,"In Progress") -> 0
A8: Days Not Started | B8: =COUNTIF('Daily Plan'!G5:G56,"Not Started") -> 0
A10: Exercises Covered (should be 40) | B10: 40
A12: C1 Due (count) | B12: =COUNTIF('Daily Plan'!H5:H56,">0") -> 52
A13: C1 Marked Yes | B13: =COUNTIF('Daily Plan'!I5:I56,"Yes") -> 7
