Workbook

Sheet Master Schedule
A1: Order | B1: Planned Date | C1: Task Type | D1: Phase | E1: Section(s) | F1: Task | G1: Exercise | H1: Related Result / Reason | I1: Prerequisite | J1: Proceed Gate | K1: Actual Start | L1: Actual End (exercise auto) | M1: First-pass Status | N1: Key Blocker | O1: Suggested Redo Date (auto) | P1: Actual Redo Date | Q1: Redo Result | R1: Proceed? | S1: Notes
A2: 1 | B2: 46272 | C2: Read | D2: A. Meaning of weak convergence | E2: 8.1 | F2: Read the basic definitions. Separate vague, proper, weak, and complete convergence; mark exactly where continuity points of the limit df enter. | I2: Start of Chapter 8 | K2: 46272 | L2: =IF($P2<>"",$P2,"")
A3: 2 | B3: 46273 | C3: Read | D3: A. Meaning of weak convergence | E3: 8.1 | F3: Read Theorem 8.1.1, weak-limit uniqueness, and Examples 8.1.1–8.1.2. Make a one-page comparison: what converges, what does not, and why the limit must be proper. | H3: Equivalence of the four definitions / uniqueness | I3: 8.1 definitions read | L3: =IF($P3<>"",$P3,"")
A4: 3 | B4: 46274 | C4: Exercise | D4: A. Meaning of weak convergence | E4: 8.1 / Ch6 bridge | F4: Do Exercise 2: rare spikes; compare convergence in probability, distribution, and almost sure convergence. | G4: Ex 2 | H4: 8.1 + Chapter 6 convergence hierarchy | I4: 8.1 read | L4: =IF($P4<>"",$P4,"") | O4: =IF($P4<>"",$P4,"")
A5: 4 | B5: 46275 | C5: Exercise | D5: A. Meaning of weak convergence | E5: 8.1 / 8.2 | F5: Do Exercise 4: discrete weak convergence, event indicators, point masses, and the mass-function caveat. Treat it as one multi-part exercise. | G5: Ex 4 | H5: Core mechanics of weak convergence; Scheffe bridge | I5: Exercise 2 attempted | L5: =IF($P5<>"",$P5,"") | O5: =IF(AND($K5<>"",$M5<>""),$K5+VLOOKUP($M5,'Redo Rules'!$A$2:$D$5,4,FALSE),"")
A6: 5 | B6: 46276 | C6: Exercise | D6: A. Meaning of weak convergence | E6: 8.1 / 8.5 | F6: Do Exercise 10: construct weak convergence without convergence in probability. | G6: Ex 10 | H6: Why distributional convergence does not control the original coupling | I6: Exercise 4 attempted | L6: =IF($P6<>"",$P6,"") | O6: =IF(AND($K6<>"",$M6<>""),$K6+VLOOKUP($M6,'Redo Rules'!$A$2:$D$5,4,FALSE),"")
A7: 6 | B7: 46277 | C7: Exercise | D7: A. Meaning of weak convergence | E7: 8.1 | F7: Do Exercise 18: give a discrete sequence converging weakly to a distribution with a density. | G7: Ex 18 | H7: Discrete-to-continuous weak convergence intuition | I7: Exercise 10 attempted | L7: =IF($P7<>"",$P7,"") | O7: =IF(AND($K7<>"",$M7<>""),$K7+VLOOKUP($M7,'Redo Rules'!$A$2:$D$5,4,FALSE),"")
A8: 7 | B8: 46278 | C8: Gate | D8: A. Meaning of weak convergence | E8: 8.1 | F8: Proceed gate: explain, without formulas first, why convergence in distribution is a statement about laws rather than pointwise behavior of the original random variables; then state the continuity-point definition precisely. | H8: Gate before Scheffe | I8: Exercises 2, 4, 10, 18 attempted | J8: Proceed only if you can distinguish weak convergence from a.s./i.p. convergence and explain the role of C(F). | L8: =IF($P8<>"",$P8,"")
A9: 8 | B9: 46279 | C9: Read | D9: B. Scheffe and order statistics | E9: 8.2 | F9: Read Scheffe's lemma. Record both directions carefully: what density convergence is sufficient for, and what weak convergence does NOT imply about densities. | H9: Total variation and L1 density distance | I9: Block A gate passed | L9: =IF($P9<>"",$P9,"")
A10: 9 | B10: 46280 | C10: Read | D10: B. Scheffe and order statistics | E10: 8.2.1 | F10: Read the order-statistics application. Focus on how density asymptotics plus Scheffe turn into convergence in distribution; keep the normalization visible. | H10: Order statistics application of Scheffe | I10: 8.2 read | L10: =IF($P10<>"",$P10,"")
A11: 10 | B11: 46281 | C11: Exercise | D11: B. Scheffe and order statistics | E11: 8.2 | F11: Do Exercise 12: weak convergence to Uniform[0,1] while the densities fail to converge. | G11: Ex 12 | H11: Scheffe caveat / weak vs density convergence | I11: 8.2 read | L11: =IF($P11<>"",$P11,"") | O11: =IF(AND($K11<>"",$M11<>""),$K11+VLOOKUP($M11,'Redo Rules'!$A$2:$D$5,4,FALSE),"")
A12: 11 | B12: 46282 | C12: Exercise | D12: B. Scheffe and order statistics | E12: 8.2.1 | F12: Do Exercise 8: exponential order statistics and the Gamma limit. | G12: Ex 8 | H12: Order statistics; direct method vs Renyi spacing representation | I12: 8.2.1 read | L12: =IF($P12<>"",$P12,"") | O12: =IF(AND($K12<>"",$M12<>""),$K12+VLOOKUP($M12,'Redo Rules'!$A$2:$D$5,4,FALSE),"")
A13: 12 | B13: 46283 | C13: Exercise | D13: B. Scheffe and order statistics | E13: 8.2.1 | F13: Do Exercise 22: sample median / order-statistic limit using Scheffe's lemma. | G13: Ex 22 | H13: Scheffe + asymptotic order statistics | I13: Exercise 8 attempted | L13: =IF($P13<>"",$P13,"") | O13: =IF(AND($K13<>"",$M13<>""),$K13+VLOOKUP($M13,'Redo Rules'!$A$2:$D$5,4,FALSE),"")
A14: 13 | B14: 46284 | C14: Gate | D14: B. Scheffe and order statistics | E14: 8.2–8.2.1 | F14: Proceed gate: distinguish weak convergence, total variation convergence, pointwise density convergence, and L1 density convergence. State exactly what Scheffe gives and what it does not give. | H14: Gate before Skorohod / mapping | I14: Block B exercises attempted | J14: Proceed only if the implication arrows are explicit and you have one counterexample for a false converse. | L14: =IF($P14<>"",$P14,"")
A15: 14 | B15: 46285 | C15: Read | D15: C. Skorohod, mapping, and delta | E15: 8.3 | F15: Read Proposition 8.3.1, Lemma 8.3.1, and the Baby Skorohod Theorem. Track the quantile construction and the crucial caveat: one-dimensional laws are matched, original dependence is not. | H15: Baby Skorohod coupling / quantile map | I15: Block B gate passed | L15: =IF($P15<>"",$P15,"")
A16: 15 | B16: 46286 | C16: Read | D16: C. Skorohod, mapping, and delta | E16: 8.3–8.3.1 | F16: Read the Continuous Mapping Theorem and Delta Method. Separate the formal theorem from the intuition: continuity transfers the limit; the delta method is first-order linearization. | H16: Continuous mapping + delta method | I16: 8.3 read | L16: =IF($P16<>"",$P16,"")
A17: 16 | B17: 46287 | C17: Exercise | D17: C. Skorohod, mapping, and delta | E17: 8.3.1 | F17: Do Exercise 1: binomial estimator and the log-odds transformation by the delta method. | G17: Ex 1 | H17: Delta method in statistical estimation | I17: 8.3.1 read | L17: =IF($P17<>"",$P17,"") | O17: =IF(AND($K17<>"",$M17<>""),$K17+VLOOKUP($M17,'Redo Rules'!$A$2:$D$5,4,FALSE),"")
A18: 17 | B18: 46288 | C18: Exercise | D18: C. Skorohod, mapping, and delta | E18: 8.3.1 | F18: Do Exercise 7: transformed sample means; identify the derivative and limiting scale before calculating. | G18: Ex 7 | H18: Delta-method mechanics | I18: Exercise 1 attempted | L18: =IF($P18<>"",$P18,"") | O18: =IF(AND($K18<>"",$M18<>""),$K18+VLOOKUP($M18,'Redo Rules'!$A$2:$D$5,4,FALSE),"")
A19: 18 | B19: 46289 | C19: Exercise | D19: C. Skorohod, mapping, and delta | E19: 8.3 | F19: Do Exercise 19: the second continuous mapping theorem. | G19: Ex 19 | H19: Mapping theorem with n-dependent maps | I19: Exercise 7 attempted | L19: =IF($P19<>"",$P19,"") | O19: =IF(AND($K19<>"",$M19<>""),$K19+VLOOKUP($M19,'Redo Rules'!$A$2:$D$5,4,FALSE),"")
A20: 19 | B20: 46290 | C20: Exercise | D20: C. Skorohod, mapping, and delta | E20: 8.3.1 / 8.6 | F20: Do Exercise 23: multi-part delta-method and sample-variance problem. Protected deep exercise: if it needs more than one day, shift the schedule; do not start a new exercise in parallel. | G20: Ex 23 | H20: Delta method + sample variance + Slutsky-style reasoning | I20: Exercise 19 attempted | L20: =IF($P20<>"",$P20,"") | O20: =IF(AND($K20<>"",$M20<>""),$K20+VLOOKUP($M20,'Redo Rules'!$A$2:$D$5,4,FALSE),"")
A21: 20 | B21: 46291 | C21: Gate | D21: C. Skorohod, mapping, and delta | E21: 8.3–8.3.1 | F21: Proceed gate: explain why Skorohod is a coupling device rather than a claim about the original variables, and reproduce the delta-method proof skeleton as 'linearization + negligible remainder + limit transfer'. | H21: Gate before Portmanteau | I21: Block C exercises attempted | J21: Proceed only if the logical use of Skorohod/CMT is clear; do not memorize the coupling construction without its purpose.
A22: 21 | B22: 46292 | C22: Read | D22: D. Portmanteau and the convergence map | E22: 8.4 | F22: Read the Portmanteau Theorem and its proof. Build a three-row equivalence table: df at continuity points, bounded continuous test functions, and continuity sets. | H22: Portmanteau theorem | I22: Block C gate passed
A23: 22 | B23: 46293 | C23: Read | D23: D. Portmanteau and the convergence map | E23: 8.5 | F23: Read the relations among modes of convergence. Add Chapter 8 to your Chapter 6 convergence map, including the special constant-limit equivalence between i.p. and distribution. | H23: a.s. => i.p. => distribution; constant-limit converse | I23: 8.4 read
A24: 23 | B24: 46294 | C24: Exercise | D24: D. Portmanteau and the convergence map | E24: 8.4 | F24: Do Exercise 5: monotone functions converging to a continuous limit; derive uniform convergence of cdfs when the weak limit is continuous. | G24: Ex 5 | H24: Continuity-point convergence strengthened by monotonicity | I24: 8.4 read | L24: =IF($P24<>"",$P24,"") | O24: =IF(AND($K24<>"",$M24<>""),$K24+VLOOKUP($M24,'Redo Rules'!$A$2:$D$5,4,FALSE),"")
A25: 24 | B25: 46295 | C25: Exercise | D25: D. Portmanteau and the convergence map | E25: 8.4 | F25: Do Exercise 9: characterize weak convergence using continuous functions with compact support. | G25: Ex 9 | H25: Alternative Portmanteau test-function class | I25: Exercise 5 attempted | L25: =IF($P25<>"",$P25,"") | O25: =IF(AND($K25<>"",$M25<>""),$K25+VLOOKUP($M25,'Redo Rules'!$A$2:$D$5,4,FALSE),"")
A26: 25 | B26: 46296 | C26: Exercise | D26: D. Portmanteau and the convergence map | E26: 8.4 / Ch6 | F26: Do Exercise 31: weak convergence plus a uniform moment bound; use Baby Skorohod and uniform integrability to recover moment convergence. | G26: Ex 31 | H26: Weak convergence + Chapter 6 UI | I26: Exercise 9 attempted | L26: =IF($P26<>"",$P26,"") | O26: =IF(AND($K26<>"",$M26<>""),$K26+VLOOKUP($M26,'Redo Rules'!$A$2:$D$5,4,FALSE),"")
A27: 26 | B27: 46297 | C27: Exercise | D27: D. Portmanteau and the convergence map | E27: 8.1 / 8.4 | F27: Do Exercise 32: identify the Bernoulli weak limit from interior cdf convergence. | G27: Ex 32 | H27: Continuity-point logic when the limit has jumps | I27: Exercise 31 attempted | L27: =IF($P27<>"",$P27,"") | O27: =IF(AND($K27<>"",$M27<>""),$K27+VLOOKUP($M27,'Redo Rules'!$A$2:$D$5,4,FALSE),"")
A28: 27 | B28: 46298 | C28: Exercise | D28: D. Portmanteau and the convergence map | E28: 8.4 / 8.2 | F28: Do Exercise 36: reweight probability measures by a continuous density g and prove weak convergence of the new measures. | G28: Ex 36 | H28: Portmanteau / Scheffe-style change of measure | I28: Exercise 32 attempted | L28: =IF($P28<>"",$P28,"") | O28: =IF(AND($K28<>"",$M28<>""),$K28+VLOOKUP($M28,'Redo Rules'!$A$2:$D$5,4,FALSE),"")
A29: 28 | B29: 46299 | C29: Gate | D29: D. Portmanteau and the convergence map | E29: 8.4–8.5 | F29: Proceed gate: from a weak-convergence claim, choose the easiest of the three Portmanteau formulations and justify why it applies. Also reproduce the full convergence hierarchy from Chapter 6 through Chapter 8. | H29: Gate before converging-together results | I29: Block D exercises attempted | J29: Proceed only if you can switch formulations deliberately rather than automatically using cdfs.
A30: 29 | B30: 46300 | C30: Read | D30: E. Converging together and dependence | E30: 8.6 | F30: Read Slutsky's theorem and the Second Converging Together Theorem. Write the approximation template: tractable X_{u,n}, limit X_u, approximation error, then u -> infinity. | H30: Slutsky / second converging-together theorem | I30: Block D gate passed
A31: 30 | B31: 46301 | C31: Read | D31: E. Converging together and dependence | E31: 8.6.1 | F31: Read the m-dependent CLT application. First pass goal: reproduce the variance calculation and the big-block/little-block architecture; do not get lost in block bookkeeping. | H31: Hoeffding–Robbins m-dependent CLT / blocking | I31: 8.6 read | L31: =IF($P31<>"",$P31,"")
A32: 31 | B32: 46302 | C32: Exercise | D32: E. Converging together and dependence | E32: 8.1 / 8.6 | F32: Do Exercise 20: scaled geometric waiting time converges to a unit exponential. | G32: Ex 20 | H32: Direct distributional limit / scaling | I32: 8.6 read | L32: =IF($P32<>"",$P32,"") | O32: =IF(AND($K32<>"",$M32<>""),$K32+VLOOKUP($M32,'Redo Rules'!$A$2:$D$5,4,FALSE),"")
A33: 32 | B33: 46303 | C33: Exercise | D33: E. Converging together and dependence | E33: 8.1 / 8.6 | F33: Do Exercise 21: first coincidence in sampling with replacement and its non-degenerate scaling limit. | G33: Ex 21 | H33: Distributional scaling / birthday-collision limit | I33: Exercise 20 attempted | L33: =IF($P33<>"",$P33,"") | O33: =IF(AND($K33<>"",$M33<>""),$K33+VLOOKUP($M33,'Redo Rules'!$A$2:$D$5,4,FALSE),"")
A34: 33 | B34: 46304 | C34: Exercise | D34: E. Converging together and dependence | E34: 8.6 / Ch9 bridge | F34: Do Exercise 24: closure under convolution for normal, Poisson, and Cauchy types; decide what happens for the exponential type. | G34: Ex 24 | H34: Sums, types, and bridge to Chapter 9 characteristic functions | I34: Exercise 21 attempted | L34: =IF($P34<>"",$P34,"") | O34: =IF(AND($K34<>"",$M34<>""),$K34+VLOOKUP($M34,'Redo Rules'!$A$2:$D$5,4,FALSE),"")
A35: 34 | B35: 46305 | C35: Exercise | D35: E. Converging together and dependence | E35: 8.4 / CLT application | F35: Do Exercise 14: a coordinate of the uniform distribution on the sphere converges to standard normal. | G35: Ex 14 | H35: High-dimensional normalization + weak convergence | I35: Exercise 24 attempted | L35: =IF($P35<>"",$P35,"") | O35: =IF(AND($K35<>"",$M35<>""),$K35+VLOOKUP($M35,'Redo Rules'!$A$2:$D$5,4,FALSE),"")
A36: 35 | B36: 46306 | C36: Gate | D36: E. Converging together and dependence | E36: 8.6–8.6.1 | F36: Proceed gate: explain Slutsky as 'small perturbations do not change the weak limit' and explain the big-block/little-block proof as an approximation argument feeding the second converging-together theorem. | H36: Gate before convergence to types | I36: Block E exercises attempted | J36: Proceed only if you can identify the approximating object and the error term in the m-dependent CLT. | L36: =IF($P36<>"",$P36,"")
A37: 36 | B37: 46307 | C37: Read | D37: F. Convergence to types and extremes | E37: 8.7 | F37: Read the Convergence to Types Theorem. Focus on why two different normalizations of the same non-degenerate limit force the normalizing constants themselves to converge. | H37: Convergence to Types Theorem | I37: Block E gate passed | L37: =IF($P37<>"",$P37,"")
A38: 37 | B38: 46308 | C38: Read | D38: F. Convergence to types and extremes | E38: 8.7.1 | F38: Read the extreme-value application. First pass: record the seven-step proof architecture and the three possible limit types; only deepen a functional-equation step if it blocks the architecture. | H38: Extreme-value limit types | I38: 8.7 read | L38: =IF($P38<>"",$P38,"")
A39: 38 | B39: 46309 | C39: Exercise | D39: F. Convergence to types and extremes | E39: 8.7 | F39: Do Exercise 6: affine uniqueness for a non-degenerate distribution. This is the lemma used inside the convergence-to-types proof. | G39: Ex 6 | H39: Uniqueness of affine type parameters | I39: 8.7 read | L39: =IF($P39<>"",$P39,"") | O39: =IF(AND($K39<>"",$M39<>""),$K39+VLOOKUP($M39,'Redo Rules'!$A$2:$D$5,4,FALSE),"")
A40: 39 | B40: 46310 | C40: Exercise | D40: F. Convergence to types and extremes | E40: 8.7.1 | F40: Do Exercise 17: normalize maxima of iid Uniform(0,1) variables and find a non-degenerate limit. | G40: Ex 17 | H40: Elementary extreme-value normalization | I40: 8.7.1 read | L40: =IF($P40<>"",$P40,"") | O40: =IF(AND($K40<>"",$M40<>""),$K40+VLOOKUP($M40,'Redo Rules'!$A$2:$D$5,4,FALSE),"")
...

Sheet Dashboard
A1: Resnick Chapter 8 Schedule
A2: Instruction: B3 records the baseline start date; Planned Date is a reference schedule, not a pace target. Fill Actual Start. For exercises, diagnose the first pass, then use the automatic redo date. Exercise Actual End is the actual redo date.
A3: Plan start date (edit) | B3: 46272
A4: Total scheduled tasks | B4: =COUNTA('Master Schedule'!A2:A64) -> 46
A5: Reading rows | B5: =COUNTIF('Master Schedule'!C2:C64,"Read") -> 12
A6: Exercise rows (core scheduled) | B6: =COUNTIF('Master Schedule'!C2:C64,"Exercise") -> 26
A7: Gate rows | B7: =COUNTIF('Master Schedule'!C2:C64,"Gate") -> 6
A8: Summary rows | B8: =COUNTIF('Master Schedule'!C2:C64,"Summary") -> 2
A9: Optional / unscheduled exercises | B9: =COUNTIF('Exercise Map'!F4:F39,"No") -> 10
A10: Actual redo dates filled | B10: =COUNT('Master Schedule'!P2:P64) -> 0
A11: Redo due / unresolved | B11: =COUNTIFS('Master Schedule'!O2:O64,"<="&TODAY(),'Master Schedule'!O2:O64,">0",'Master Schedule'!P2:P64,"") -> 0
A13: Totally ignorance | B13: =COUNTIF('Master Schedule'!M2:M64,"Totally ignorance") -> 0
A14: Spark | B14: =COUNTIF('Master Schedule'!M2:M64,"Spark") -> 0
A15: Skeleton | B15: =COUNTIF('Master Schedule'!M2:M64,"Skeleton") -> 0
A16: Crack it | B16: =COUNTIF('Master Schedule'!M2:M64,"Crack it") -> 0
A17: Main fill-out columns | B17: K, M:N, P:Q, R:S in Master Schedule
A18: Depth-control rule | B18: Core schedule first; optional exercises are promoted only after a block gate or after the chapter summary.

Sheet Redo Rules
A1: First-pass Status | B1: Meaning | C1: Recommended Action | D1: Redo Offset Days
A2: Totally ignorance | B2: Cannot write meaningful structure. | C2: Redo next day after rereading the exact theorem/definition; ask for minimum hint only if still blank. | D2: 1
A3: Spark | B3: Blur picture appears but needs ignition. | C3: Redo after two days with one minimum hint. | D3: 2
A4: Skeleton | B4: Direction is right but missing the logical bridge. | C4: Redo after two days; focus only on the missing bridge. | D4: 2
A5: Crack it | B5: Logic basically correct. | C5: C1 after two days; no immediate full rewrite unless the proof was messy. | D5: 2
A6: Note | B6: Actual Start is the first-attempt date. Suggested Redo Date = Actual Start + status offset. Exercise Actual End = Actual Redo Date.
A8: Chapter 8 Depth-Control Rules
A9: Core before optional | B9: Complete the scheduled core exercise set before promoting Advanced/Optional items. | C9: A Useful exercise may be promoted after its block gate if it tests a genuinely different idea.
A10: Heavy exercise | B10: Ex 4, 16, and 23 may legitimately take more than one day. | C10: Freeze the schedule and continue the same exercise; do not open another exercise merely to keep the calendar moving.
A11: Equivalence / alternate-proof trap | B11: Do not expand one exercise into every possible direction by default. | C11: After one correct proof and one genuinely illuminating alternative, ask whether another direction changes the chapter architecture. If not, park it.
A12: Block gate | B12: A gate checks architecture, not perfection. | C12: Technical gaps become redo items; a gate should prevent details from erasing the big picture.
A13: Final redo | B13: Redo still matters even when the first proof was basically correct. | C13: The goal is independent reproduction, not merely recognizing the book's argument.
A14: Optional sweep | B14: Optional exercises are not 'failed' or 'skipped'. | C14: After the chapter summary, choose them only for a specific conceptual reason.
A15: Minefield protocol | B15: When an exercise is shared in chat, diagnose the user's literal idea first. | C15: Identify the exact logical gap before giving hints; do not jump directly to a full solution.
A16: Summary rule | B16: Chapter summary is architectural reconstruction. | C16: Organize it by definitions, main results, proof ideas, technical tricks, pitfalls, and connections.

Sheet Exercise Map
A1: Chapter 8 Exercise Map — all 36 exercises
A2: Descriptions below are planning summaries, not replacements for the book's problem statements. Priority and scheduling are our study-plan judgments.
A3: Exercise | B3: Primary Tool / Section | C3: Planning Summary | D3: Role | E3: Priority | F3: Scheduled? | G3: Suggested After | H3: Depth Risk | I3: Planning Note
A4: 1 | B4: 8.3.1 Delta Method | C4: Binomial estimator; delta method for log-odds | D4: Core | E4: Core | F4: Yes | G4: 8.3.1 | H4: Normal | I4: Statistical meaning + mechanics.
A5: 2 | B5: 8.1 / 8.5 | C5: Rare spikes; compare i.p., weak, and a.s. convergence | D5: Core | E5: Core | F5: Yes | G5: 8.1 | H5: Normal | I5: Excellent convergence-mode counterexample.
A6: 3 | B6: 8.1 / Ch7–9 bridge | C6: Products of uniforms; a.s. limit and centered/scaled weak limit | D6: Extension | E6: Useful | F6: No | G6: Block A or Chapter 9 | H6: Normal | I6: Good bridge, but not needed for the Chapter 8 backbone.
A7: 4 | B7: 8.1 / 8.2 | C7: Discrete weak convergence, Scheffe, events, point masses, mass-function caveat | D7: Core | E7: Core | F7: Yes | G7: 8.1 | H7: Multi-part | I7: Treat as one exercise; pause schedule if needed.
A8: 5 | B8: 8.4 | C8: Monotone functions and uniform cdf convergence with continuous limit | D8: Core | E8: Core | F8: Yes | G8: 8.4 | H8: Normal | I8: Strengthens continuity-point convergence.
A9: 6 | B9: 8.7 | C9: Affine uniqueness lemma for a non-degenerate df | D9: Core | E9: Core | F9: Yes | G9: 8.7 | H9: Normal | I9: A proof component of convergence to types.
A10: 7 | B10: 8.3.1 | C10: Delta-method transforms of sample means | D10: Core | E10: Core | F10: Yes | G10: 8.3.1 | H10: Normal | I10: Repetition is useful here because derivatives/scales should become automatic.
A11: 8 | B11: 8.2.1 | C11: Exponential order statistic -> Gamma limit | D11: Core | E11: Core | F11: Yes | G11: 8.2.1 | H11: Normal | I11: Compare brute-force and Renyi-spacing approaches.
A12: 9 | B12: 8.4 | C12: Compact-support test functions characterize weak convergence | D12: Core | E12: Core | F12: Yes | G12: 8.4 | H12: Normal | I12: Portmanteau refinement.
A13: 10 | B13: 8.1 / 8.5 | C13: Weak convergence without convergence in probability | D13: Core | E13: Core | F13: Yes | G13: 8.1 | H13: Normal | I13: Locks in the coupling distinction.
A14: 11 | B14: 8.4 | C14: Levy metric metrizes weak convergence | D14: Theory Extension | E14: Advanced/Optional | F14: No | G14: After Block D | H14: High | I14: Valuable topology, but can become a long technical detour.
A15: 12 | B15: 8.2 | C15: Weak convergence while densities do not converge | D15: Core | E15: Core | F15: Yes | G15: 8.2 | H15: Normal | I15: Direct warning against confusing weak and density convergence.
... A39: 36 | B39: 8.4 / 8.2 | C39: Continuous reweighting of measures preserves weak convergence | D39: Core Extension | E39: Core | F39: Yes | G39: 8.4 | H39: Medium | I39: Good synthesis of test functions and density ideas.
