Workbook

Sheet Master Schedule
A1: Order | B1: Planned Date | C1: Section | D1: Reading / Theory Task | E1: Proof Tell-Back Goal | F1: New Exercise | G1: Exercise Role | H1: Required Material | I1: Exit Check / Planning Note | J1: Actual Reading Date | K1: Actual Proof Date | L1: Actual Exercise Date | M1: Initial Grade | N1: Key Blocker | O1: Repair Passed? | P1: Suggested Redo Date (auto) | Q1: Actual Redo Date | R1: Redo Result | S1: RMarkdown | T1: Notes
A2: 1 | B2: 46273 | C2: 8.1 carry-in | F2: Ex 2 | G2: Local / completed | H2: 8.1 + Chapter 6 convergence notions | I2: Already repaired and passed before this rebuilt plan. Keep the original first-attempt grade fixed; use this row for the spaced redo record. | L2: 46273 | M2: Skeleton | P2: =IF(AND($L2<>"",$M2<>""),$L2+VLOOKUP($M2,'Redo Rules'!$A$2:$D$5,4,FALSE),"") -> 46275 | Q2: 46278 | T2: Fill the actual exercise date/grade from your own record if you want the redo formula to activate.
A3: 2 | B3: 46274 | C3: 8.2 | D3: Read Section 8.2 through Scheffe's lemma. Separate pointwise density convergence, L1 convergence, total variation, and weak convergence. Notice the counting-measure remark. | E3: Tell what Scheffe's proof is doing: where the sign split comes from, why the positive/negative parts balance, and why this yields the L1/total-variation conclusion. | H3: 8.1 learned | I3: Immediate next action from the current position.
A4: 3 | B4: 46275 | C4: 8.2 | F4: Ex 4 | G4: Section-local / core | H4: Read 8.2 and be able to explain Scheffe; part (b) explicitly uses it. | I4: Resume the exercise that was paused because the prerequisite was missing. The pause is not a failed attempt. | L4: 46276 | M4: Skeleton | P4: =IF(AND($L4<>"",$M4<>""),$L4+VLOOKUP($M4,'Redo Rules'!$A$2:$D$5,4,FALSE),"") -> 46278 | Q4: 46278 | T4: Protected multi-part exercise: if it needs >1 day, continue it and shift later dates.
A5: 4 | B5: 46276 | C5: 8.2 | F5: Ex 12 | G5: Section-local / core | H5: 8.2 Scheffe | I5: Section check: explain why weak convergence does not force density convergence. | L5: 46277 | M5: Crack it | P5: =IF(AND($L5<>"",$M5<>""),$L5+VLOOKUP($M5,'Redo Rules'!$A$2:$D$5,4,FALSE),"") -> 46279
A6: 5 | B6: 46277 | C6: 8.1 carryover | F6: Ex 18 | G6: Section-local / core | H6: 8.1 | I6: Catch up the remaining 8.1 local exercises after resolving the Ex 4 prerequisite issue. | L6: 46278 | M6: Crack it | P6: =IF(AND($L6<>"",$M6<>""),$L6+VLOOKUP($M6,'Redo Rules'!$A$2:$D$5,4,FALSE),"") -> 46280
A7: 6 | B7: 46278 | C7: 8.1 carryover | F7: Ex 20 | G7: Section-local application / core | H7: 8.1 | I7: Direct scaling/cdf practice. | L7: 46279 | M7: Crack it | P7: =IF(AND($L7<>"",$M7<>""),$L7+VLOOKUP($M7,'Redo Rules'!$A$2:$D$5,4,FALSE),"") -> 46281
A8: 7 | B8: 46279 | C8: 8.1 carryover | F8: Ex 21 | G8: Section-local application / core | H8: 8.1 | I8: Nontrivial cdf scaling application. | L8: 46279 | M8: Skeleton | P8: =IF(AND($L8<>"",$M8<>""),$L8+VLOOKUP($M8,'Redo Rules'!$A$2:$D$5,4,FALSE),"") -> 46281
A9: 8 | B9: 46280 | C9: 8.1 carryover | F9: Ex 32 | G9: Section-local / core | H9: 8.1 continuity-point definition | I9: 8.1 exit check: explain continuity-point convergence when the limit df has jumps. | P9: =IF(AND($L9<>"",$M9<>""),$L9+VLOOKUP($M9,'Redo Rules'!$A$2:$D$5,4,FALSE),"")
A10: 9 | B10: 46281 | C10: 8.2.1 | D10: Read the order-statistics application of Scheffe. Track the order-statistic density, normalization, Stirling step, and where Scheffe finishes the argument. | E10: Architecture only: density -> normalization -> pointwise density limit -> Scheffe -> weak limit. Mark the later 8.7 normalization reference and move on. | H10: 8.2 passed | I10: Do not reconstruct every Stirling/bookkeeping line unless it blocks the architecture. | J10: 46274
A11: 10 | B11: 46282 | C11: 8.2.1 | F11: Ex 8 | G11: Section-local / core | H11: 8.2.1; Renyi spacings from Chapter 4 only if using the second route. | I11: Compare direct and spacing routes only if the second adds insight. | P11: =IF(AND($L11<>"",$M11<>""),$L11+VLOOKUP($M11,'Redo Rules'!$A$2:$D$5,4,FALSE),"")
A12: 11 | B12: 46283 | C12: 8.2.1 | F12: Ex 22 | G12: Section-local / core | H12: 8.2.1 + Scheffe | I12: Section exit: identify the common density->Scheffe pattern in Ex 8/22. | P12: =IF(AND($L12<>"",$M12<>""),$L12+VLOOKUP($M12,'Redo Rules'!$A$2:$D$5,4,FALSE),"")
A13: 12 | B13: 46284 | C13: 8.3 | D13: Read the quantile lemma and Baby Skorohod theorem. Keep the distinction between matching laws and preserving the original dependence. | E13: Tell the chain: quantile convergence -> construct X_n^# with the same marginal laws -> almost-sure convergence on a new space. | H13: 8.2.1 passed | I13: Focus on why the constructed probability space is useful.
A14: 13 | B14: 46285 | C14: 8.3 | D14: Read the Continuous Mapping Theorem and its discontinuity-set condition. | E14: Tell what the proof is doing: use the Skorohod coupling, apply ordinary continuity almost surely away from Disc(h), then return to weak convergence. | H14: Baby Skorohod understood
A15: 14 | B15: 46286 | C15: 8.3 | F15: Ex 19 | G15: Section-local / core | H15: 8.3 Continuous Mapping Theorem | I15: 8.3 exit: distinguish a mapping theorem on the original variables from a coupling proof on the constructed space. | P15: =IF(AND($L15<>"",$M15<>""),$L15+VLOOKUP($M15,'Redo Rules'!$A$2:$D$5,4,FALSE),"")
A16: 15 | B16: 46287 | C16: 8.3.1 | D16: Read the Delta Method. Separate the theorem statement from the first-order Taylor expansion that drives the proof. | E16: Tell the proof as linearization + negligible remainder + transfer of the existing weak limit. Identify the role of g'(theta). | H16: 8.3 passed
A17: 16 | B17: 46288 | C17: 8.3.1 | F17: Ex 1 | G17: Section-local / core | H17: 8.3.1 + assumed CLT | I17: Statistical estimator/pivot application. | P17: =IF(AND($L17<>"",$M17<>""),$L17+VLOOKUP($M17,'Redo Rules'!$A$2:$D$5,4,FALSE),"")
A18: 17 | B18: 46289 | C18: 8.3.1 | F18: Ex 7 | G18: Section-local / core | H18: 8.3.1 + assumed CLT | I18: Before calculating, identify derivative and scaling. | P18: =IF(AND($L18<>"",$M18<>""),$L18+VLOOKUP($M18,'Redo Rules'!$A$2:$D$5,4,FALSE),"")
A19: 18 | B19: 46290 | C19: 8.4 | D19: Read the Portmanteau theorem. First map the equivalent formulations: cdf at continuity points, bounded continuous test functions, and continuity sets. | E19: Tell what each implication is doing. Concentrate reconstruction effort on the nontrivial converse/indicator-approximation step rather than reciting every line. | H19: 8.3.1 local exercises done | I19: Portmanteau is a chapter backbone; architecture matters more than verbatim proof reproduction.
A20: 19 | B20: 46291 | C20: 8.4 | F20: Ex 33 | G20: Supporting / core | H20: Basic properties of continuous dfs | I20: Quick supporting exercise before Ex 5; it supplies uniform continuity of a continuous df. | P20: =IF(AND($L20<>"",$M20<>""),$L20+VLOOKUP($M20,'Redo Rules'!$A$2:$D$5,4,FALSE),"")
A21: 20 | B21: 46292 | C21: 8.4 | F21: Ex 5 | G21: Cumulative / core | H21: 8.1 + 8.4; Ex 33 useful | I21: Strengthen pointwise/weak cdf convergence to uniform convergence when the limit is continuous. | P21: =IF(AND($L21<>"",$M21<>""),$L21+VLOOKUP($M21,'Redo Rules'!$A$2:$D$5,4,FALSE),"")
A22: 21 | B22: 46293 | C22: 8.4 | F22: Ex 9 | G22: Section-local / core | H22: 8.4 Portmanteau | I22: Alternative test-function class. | P22: =IF(AND($L22<>"",$M22<>""),$L22+VLOOKUP($M22,'Redo Rules'!$A$2:$D$5,4,FALSE),"")
A23: 22 | B23: 46294 | C23: 8.4 | F23: Ex 36 | G23: Cumulative synthesis / core | H23: 8.4; Scheffe from 8.2 is an optional route | I23: Section exit: deliberately choose between direct weak-convergence and Scheffe routes. | P23: =IF(AND($L23<>"",$M23<>""),$L23+VLOOKUP($M23,'Redo Rules'!$A$2:$D$5,4,FALSE),"")
A24: 23 | B24: 46295 | C24: 8.5 | D24: Read the relations among modes of convergence and the special constant-limit converse. | E24: Tell the convergence map in words: what each arrow means, why converses fail in general, and why a constant limit is special. | H24: 8.4 passed
A25: 24 | B25: 46296 | C25: 8.5 | F25: Ex 10 | G25: Cumulative / core | H25: 8.1 + Chapter 6; placed here for the convergence-map interpretation. | I25: Use it as a counterexample that fixes the weak-vs-probability distinction. | P25: =IF(AND($L25<>"",$M25<>""),$L25+VLOOKUP($M25,'Redo Rules'!$A$2:$D$5,4,FALSE),"")
A26: 25 | B26: 46297 | C26: 8.5 | F26: Ex 31 | G26: Cumulative / core | H26: Baby Skorohod (8.3) + Chapter 6 uniform integrability | I26: 8.5 exit: weak convergence alone is not moment convergence; identify the extra uniform-integrability control. | P26: =IF(AND($L26<>"",$M26<>""),$L26+VLOOKUP($M26,'Redo Rules'!$A$2:$D$5,4,FALSE),"")
A27: 26 | B27: 46298 | C27: 8.6 | D27: Read Slutsky and the Second Converging Together Theorem. Identify the common approximation principle. | E27: Tell Slutsky as 'small perturbations do not change the weak limit.' Tell converging together as approximation -> approximate limit -> small error -> target limit. | H27: 8.5 passed
A28: 27 | B28: 46299 | C28: 8.6 | F28: Ex 14 | G28: Section-local application / core | H28: 8.6 + Chapter 7 SLLN | I28: Normalize the sphere coordinate via a normal representation and Slutsky-type reasoning. | P28: =IF(AND($L28<>"",$M28<>""),$L28+VLOOKUP($M28,'Redo Rules'!$A$2:$D$5,4,FALSE),"")
A29: 28 | B29: 46300 | C29: 8.6 | F29: Ex 23 | G29: Cumulative / core | H29: 8.3.1 Delta Method + assumed CLT + 8.6 Slutsky/converging-together perspective | I29: Protected deep exercise. Treat the five parts as one exercise; if it needs extra days, shift later dates rather than opening another new exercise. | P29: =IF(AND($L29<>"",$M29<>""),$L29+VLOOKUP($M29,'Redo Rules'!$A$2:$D$5,4,FALSE),"")
A30: 29 | B30: 46301 | C30: 8.6.1 | D30: Read the m-dependent CLT application. | E30: Architecture only: variance asymptotics -> big/small blocks -> independent approximation -> negligible remainder -> converging together. | H30: 8.6 understood | I30: No new exercise is forced here; the application proof itself is the practice.
A31: 30 | B31: 46302 | C31: 8.6–8.6.1 | E31: Section gate: explain what the approximating object is and where the error term is controlled in the m-dependent CLT. | H31: 8.6.1 read | I31: Architecture gate; technical bookkeeping can remain a redo note.
A32: 31 | B32: 46303 | C32: 8.7 | D32: Read the Convergence to Types theorem. | E32: Tell the proof architecture. Focus on the quantile argument that identifies scale and centering constants; do not turn it into a line-by-line recitation contest. | H32: 8.6 gate passed | I32: After this, revisit the forward-reference line marked in 8.2.1.
A33: 32 | B33: 46304 | C33: 8.7 | F33: Ex 6 | G33: Theorem-support / core | H33: 8.7 | I33: Affine uniqueness lemma that supports the type theorem. | P33: =IF(AND($L33<>"",$M33<>""),$L33+VLOOKUP($M33,'Redo Rules'!$A$2:$D$5,4,FALSE),"")
A34: 33 | B34: 46305 | C34: 8.7 | F34: Ex 26 | G34: Section-local / core | H34: 8.7 Convergence to Types | I34: 8.7 exit: explain why symmetrization removes centering and where the type theorem enters. | P34: =IF(AND($L34<>"",$M34<>""),$L34+VLOOKUP($M34,'Redo Rules'!$A$2:$D$5,4,FALSE),"")
A35: 34 | B35: 46306 | C35: 8.7.1 | D35: Read the extreme-value application and the route to the three possible limit types. | E35: Architecture only: maxima identity -> normalization consistency -> type restriction/functional equation -> three families. Mark tedious functional-equation details rather than letting them erase the big picture. | H35: 8.7 passed
A36: 35 | B36: 46307 | C36: 8.7.1 | F36: Ex 17 | G36: Section-local / core | H36: 8.7.1 | I36: Elementary maxima normalization. | P36: =IF(AND($L36<>"",$M36<>""),$L36+VLOOKUP($M36,'Redo Rules'!$A$2:$D$5,4,FALSE),"")
A37: 36 | B37: 46308 | C37: 8.7.1 | F37: Ex 27 | G37: Section-local / core | H37: 8.7.1 | I37: Extreme-value theory for minima. | P37: =IF(AND($L37<>"",$M37<>""),$L37+VLOOKUP($M37,'Redo Rules'!$A$2:$D$5,4,FALSE),"")
A38: 37 | B38: 46309 | C38: 8.7.1 | F38: Ex 34 | G38: Cumulative synthesis / core | H38: Example 8.1.2 + Delta Method 8.3.1 + 8.7.1 context | I38: Connect Delta Method to an extreme-value result. | P38: =IF(AND($L38<>"",$M38<>""),$L38+VLOOKUP($M38,'Redo Rules'!$A$2:$D$5,4,FALSE),"")
A39: 38 | B39: 46310 | C39: 8.7.1 | F39: Ex 16 | G39: Deep synthesis / core | H39: 8.7.1 + Chapter 7 regular variation/heavy-tail background | I39: Protected deep exercise. Keep the Chapter 7 connection explicit; if it expands, extend this exercise rather than adding parallel new exercises. | P39: =IF(AND($L39<>"",$M39<>""),$L39+VLOOKUP($M39,'Redo Rules'!$A$2:$D$5,4,FALSE),"")
A40: 39 | B40: 46311 | C40: 8.7–8.7.1 | E40: Section gate: state Convergence to Types, explain what non-degeneracy prevents, and describe conceptually why the three extreme-value families arise. | H40: 8.7.1 core exercises attempted | I40: Architecture gate before final synthesis.
...

Sheet Dashboard
A1: Chapter 8 Study Dashboard
A2: Current rule set: learn section-by-section, tell what each important proof is doing, do at most one NEW exercise per day, and run redo work in parallel. Cumulative and post-chapter exercises are placed by prerequisite and pedagogical value, not by exercise number.
A4: Metric | B4: Value | D4: Current Position | E4: Status | F4: Action
A5: Scheduled core exercises | B5: =COUNTIF('Exercise Map'!F4:F39,"Yes") -> 26 | D5: 8.1 | E5: Learned | F5: Local carryover Ex 18/20/21/32 remains.
A6: Post-chapter / optional exercises | B6: =COUNTIF('Exercise Map'!F4:F39,"No") -> 10 | D6: Proof tell-backs | E6: Lemma 8.1.1 + Thm 8.1.1 done | F6: No need to repeat them now.
A7: Core exercises with actual date | B7: =COUNT('Master Schedule'!L2:L43) -> 6 | D7: Ex 2 | E7: Repaired and passed | F7: Use the normal spaced redo routine.
A8: Redo due and unresolved | B8: =COUNTIFS('Master Schedule'!P2:P43,"<="&TODAY(),'Master Schedule'!P2:P43,">0",'Master Schedule'!Q2:Q43,"") -> 4 | D8: Ex 4 | E8: Paused | F8: Read/tell back Scheffe, then resume.
A9: Sections with completion date | B9: =COUNT('Section Plan'!J4:J14) -> 0 | D9: Next section | E9: 8.2 | F9: Immediate next action is Scheffe.
A12: Core Study Flow
A13: 1 | B13: Learn section | C13: Understand definitions/results with the book open
A14: 2 | B14: Proof tell-back | C14: Explain what the proof is doing; deepen only the critical step if needed
A15: 3 | B15: Local exercise | C15: At most one new exercise that day
A16: 4 | B16: Parallel redo | C16: Any due redo may be done the same day; it does not consume the new-exercise slot
A17: 5 | B17: Section gate | C17: Check architecture before moving on
A18: 6 | B18: After chapter | C18: Choose bridge/optional exercises only for a specific reason
A20: Protected Deep Exercises
A21: Ex 4 | B21: Multi-part discrete/Scheffe exercise | C21: If it needs multiple days, continue the same exercise and shift later planned dates.
A22: Ex 23 | B22: Five-part Delta/variance synthesis | C22: Treat as one exercise; do not split attention across another new exercise.
A23: Ex 16 | B23: Regular variation/extremes | C23: Allow extra depth because it connects directly back to Chapter 7 heavy tails.

Sheet Redo Rules
A1: First-pass Status | B1: Meaning | C1: Recommended Action | D1: Redo Offset Days
A2: Totally ignorance | B2: Cannot write meaningful structure. | C2: Repair the exercise first. Redo next day after rereading the exact theorem/definition; ask for a minimum hint only if still blank. | D2: 1
A3: Spark | B3: A blurred idea appears but cannot yet carry the proof. | C3: Repair until pass; redo after two days, focusing on recovering the route independently. | D3: 2
A4: Skeleton | B4: Direction is right but a logical bridge is missing. | C4: Repair the bridge; redo after two days without leaning on the repaired solution. | D4: 2
A5: Crack it | B5: Logic is basically correct. | C5: C1 after two days; no immediate full rewrite unless presentation obscured the logic. | D5: 2
A7: Routine Rule | B7: Meaning | C7: Operational Rule
A8: Initial grade is fixed | B8: The grade records only the first attempt. | C8: Later repair, hints, and corrections never retroactively change the initial grade.
A9: Repair != redo | B9: Repair happens while the exercise is active; redo is a spaced independent reconstruction. | C9: RMarkdown becomes eligible after the repaired/final solution passes, even if the initial grade was low.
A10: Redo runs in parallel | B10: Redo does not consume the day's new-exercise slot. | C10: A normal study day may contain one new exercise plus any due redo. Do not slow the chapter calendar merely because a redo is due.
A11: One new exercise per day | B11: The pacing rule applies only to new exercises. | C11: Protected deep exercises (especially Ex 4, 16, 23) may take multiple days; while one is still active, do not open another new exercise.
A12: Proof tell-back counts | B12: Proof study is not just reading. | C12: Bottom line: you can tell what the theorem/lemma proof is doing. Full reconstruction is required only when the mathematical value justifies it.
A13: Prerequisite interruption | B13: An exercise invokes a theorem/lemma not yet learned. | C13: Pause the exercise, learn/tell back the needed result, then resume. The pause is not a failed attempt.
A14: Section-local vs cumulative | B14: Earliest solvable point is not always the best pedagogical point. | C14: Do section-local exercises near the section; delay cumulative exercises until the relevant tools have accumulated.
A15: Post-chapter pool | B15: Some exercises synthesize the whole chapter or point to Chapter 9. | C15: Do not treat them as backlog. Promote them only for a specific conceptual reason after the core chapter is complete.
A16: Final redo sweep | B16: Redo still matters after a basically correct first proof. | C16: At chapter end, inspect unresolved redo results and central exercises; select targeted final redos rather than mechanically redoing everything.
A17: Minefield protocol | B17: When an exercise is shared in chat, diagnose the user's literal idea first. | C17: Identify exact logical gaps before hints; do not jump directly to a full solution.

Sheet Exercise Map
A1: Chapter 8 Exercise Map — all 36 exercises
A2: The map distinguishes earliest safe point from recommended placement. 'Scheduled core' exercises appear in the main plan; optional/bridge exercises are deliberately delayed until after the chapter or promoted only for a specific reason.
A3: Exercise | B3: Earliest Safe Point | C3: Recommended Placement | D3: Type | E3: Priority | F3: Scheduled Core? | G3: Primary Tool / Section | H3: Depth Risk | I3: Planning Note
A4: 1 | B4: 8.3.1 | C4: After 8.3.1 | D4: Section-local | E4: Core | F4: Yes | G4: Delta Method | H4: Normal | I4: Binomial/log-odds estimator; direct Delta Method practice.
A5: 2 | B5: 8.1 + Ch6 | C5: After 8.1 | D5: Section-local | E5: Core | F5: Yes | G5: Convergence modes + Borel-Cantelli | H5: Normal | I5: Already completed after repair; keep its redo separate from the new-exercise slot.
A6: 3 | B6: 8.3.1 + Ch7 + CLT | C6: After chapter / optional bridge | D6: Cumulative bridge | E6: Useful | F6: No | G6: SLLN + CLT + Delta | H6: Normal | I6: Good bridge, but not needed for the Chapter 8 backbone; if you want Resnick's CLT machinery first, revisit after Chapter 9.
A7: 4 | B7: 8.2 | C7: After 8.2 | D7: Section-local | E7: Core | F7: Yes | G7: Discrete weak convergence + Scheffe | H7: Multi-part | I7: Part (b) explicitly uses Scheffe with counting measure; the old placement before 8.2 was wrong.
A8: 5 | B8: 8.1 + Ch6 | C8: After 8.4 | D8: Cumulative | E8: Core | F8: Yes | G8: Monotonicity + weak convergence | H8: Normal | I8: Natural after Portmanteau; strengthened uniform cdf convergence.
A9: 6 | B9: 8.1 | C9: With 8.7 | D9: Theorem-support | E9: Core | F9: Yes | G9: Affine uniqueness / Convergence to Types | H9: Normal | I9: Technically earlier, but pedagogically belongs with the type theorem.
A10: 7 | B10: 8.3.1 | C10: After 8.3.1 | D10: Section-local | E10: Core | F10: Yes | G10: Delta Method | H10: Normal | I10: Derivative/scaling repetition.
A11: 8 | B11: 8.2.1 | C11: After 8.2.1 | D11: Section-local | E11: Core | F11: Yes | G11: Order statistics + Scheffe | H11: Normal | I11: Direct route vs Renyi spacings if useful.
A12: 9 | B12: 8.4 | C12: After 8.4 | D12: Section-local | E12: Core | F12: Yes | G12: Portmanteau test functions | H12: Normal | I12: Compact-support characterization.
A13: 10 | B13: 8.1 + Ch6 | C13: After 8.5 | D13: Cumulative | E13: Core | F13: Yes | G13: Weak vs convergence in probability | H13: Normal | I13: Better after the convergence hierarchy is assembled.
A14: 11 | B14: 8.4 | C14: After chapter / optional | D14: Deep extension | E14: Advanced/Optional | F14: No | G14: Levy metric | H14: High | I14: Valuable topology; can become a long detour.
A15: 12 | B15: 8.2 | C15: After 8.2 | D15: Section-local | E15: Core | F15: Yes | G15: Scheffe caveat | H15: Normal | I15: Weak convergence while densities fail to converge.
... A39: 36 | B39: 8.4 (or 8.2 via Scheffe) | C39: After 8.4 | D39: Cumulative synthesis | E39: Core | F39: Yes | G39: Weak convergence + continuous reweighting | H39: Medium | I39: Book permits direct or Scheffe route.

Sheet Section Plan
A1: Chapter 8 Section-by-Section Learning Plan
A2: Cycle: learn the section -> tell what the main proof(s) are doing -> do section-local exercises -> hold cumulative/bridge exercises until their natural point -> pass the section architecture check. Redos run in parallel and do not consume the day's new-exercise slot.
A3: Section | B3: Reading Focus | C3: Proof Tell-Back Bottom Line | D3: Section-Local Core Exercises | E3: Cumulative Exercises Placed Later | F3: Post-Chapter / Optional Related | G3: Exit Check | H3: Actual Reading Complete | I3: Actual Proof Tell-Back | J3: Section Complete | K3: Notes
A4: 8.1 Basic Definitions | B4: Properness; continuity points; vague/proper/weak/complete convergence; Lemma 8.1.1; Theorem 8.1.1; uniqueness; examples. | C4: Lemma 8.1.1: dense-set extension and epsilon-room/right-continuity idea. Theorem 8.1.1: what each direction does and where properness controls tails. | D4: Ex 2, 18, 20, 21, 32 | E4: Ex 10 is intentionally revisited after 8.5 for the convergence-map interpretation. | F4: Ex 3 (bridge if desired later) | G4: Explain why weak convergence is about laws, how continuity points enter, and why properness prevents escaped mass. | K4: 8.1 reading and the two proof tell-backs are already essentially done in chat; remaining local exercises are catch-up after resolving Ex 4.
A5: 8.2 Scheffe | B5: Pointwise density convergence, L1 distance, total variation, Scheffe; counting measure for discrete distributions. | C5: Explain the sign split/positive-negative part mechanism and why it upgrades density convergence. | D5: Ex 4, 12 | F5: Ex 28 later if you want a richer oscillating-density example. | G5: Distinguish weak, total variation, pointwise-density, and L1 convergence; explain why counting measure makes pmfs densities. | K5: Ex 4(b) explicitly needs Scheffe; this is the prerequisite that forced the plan rebuild.
A6: 8.2.1 Order Statistics | B6: Order-statistic density; normalization; Scheffe application; forward reference to convergence to types. | C6: Architecture: density -> normalization -> pointwise density limit -> Scheffe -> weak limit. | D6: Ex 8, 22 | G6: Recognize the common order-statistic/Scheffe proof pattern without reproducing all Stirling bookkeeping. | K6: Mark the 8.7 normalization reference and revisit it later.
A7: 8.3 Baby Skorohod / CMT | B7: Quantile lemma; Baby Skorohod coupling; Continuous Mapping Theorem. | C7: Quantiles give a coupling with matching laws; a.s. convergence on the new space makes continuity arguments possible. | D7: Ex 19 | G7: Explain why the new variables are a proof device and why original dependence is not preserved.
A8: 8.3.1 Delta Method | B8: Delta Method statement, Taylor linearization, statistical interpretation. | C8: First-order linearization + negligible remainder + transfer of the existing weak limit. | D8: Ex 1, 7 | E8: Ex 23 after 8.6; Ex 34 after 8.7.1. | F8: Ex 3 if you want an extra SLLN/CLT/Delta bridge. | G8: Identify the derivative and scaling before algebra; explain why first order is enough.
A9: 8.4 Portmanteau | B9: Equivalent formulations via cdfs, bounded continuous functions, and continuity sets. | C9: Know what each implication does; reconstruct the nontrivial converse/indicator-approximation idea rather than every line. | D9: Ex 33, 5, 9, 36 | F9: Ex 11 and 35 are advanced extensions; Ex 28 can also be revisited here. | G9: Given a problem, deliberately choose the easiest Portmanteau formulation and justify the choice. | K9: Ex 33 is a supporting exercise before Ex 5.
A10: 8.5 Relations among modes | B10: a.s. -> i.p. -> distribution; failed converses; constant-limit exception. | C10: Tell the convergence map and explain why a constant limit makes distributional convergence imply convergence in probability. | D10: Ex 10, 31 | G10: Separate coupling information from law information; explain why weak convergence alone does not give moment convergence.
A11: 8.6 New Convergences from Old | B11: Slutsky; Second Converging Together Theorem; approximation principle. | C11: Small perturbations preserve weak limits; converging together handles tractable approximations plus small errors. | D11: Ex 14 | E11: Ex 23 is placed here as a cumulative exercise. | F11: Ex 24 is delayed to the post-chapter/Chapter 9 bridge pool. | G11: Identify the approximation, its limit, and the error term in a converging-together argument.
A12: 8.6.1 m-dependent CLT | B12: Variance asymptotics and big-block/little-block approximation. | C12: Architecture only: independent big blocks + negligible remainder + converging together. | D12: No forced new exercise | G12: Explain the proof as an application of the 8.6 approximation principle. | K12: The proof/application itself is the practice.
A13: 8.7 Convergence to Types | B13: Affine normalizations; non-degenerate limits; Convergence to Types theorem. | C13: Focus on the quantile argument that forces scale/centering constants to converge. | D13: Ex 6, 26 | F13: Ex 13 and 15 if deeper type-theorem work is desired later. | G13: State the type conclusion and explain what non-degeneracy rules out.
A14: 8.7.1 Extremes | B14: Maxima normalization; extreme-value classification; three families. | C14: Architecture: maxima identity -> normalization consistency -> type restriction -> three possible families. | D14: Ex 17, 27, 34, 16 | F14: Ex 29 and 30 are advanced normalization extensions. | G14: Describe the three extreme-value types conceptually and how convergence to types constrains the classification. | K14: Ex 16 is a protected deep exercise and a Chapter 7 heavy-tail bridge.
