Workbook

Sheet Master Schedule
A1: Order | B1: Planned Date | C1: Task Type | D1: Phase | E1: Section(s) | F1: Task | G1: Exercise | H1: Related Result / Reason | I1: Prerequisite | J1: Proceed Gate | K1: Actual Start | L1: Actual End | M1: First-pass Status | N1: Key Blocker | O1: Suggested Redo Date (auto) | P1: Redo Result | Q1: Proceed? | R1: Notes
A2: 1 | B2: 46177 | C2: Read | D2: A. WLLN foundation | E2: 7.1 | F2: Read: truncation and tail equivalence. Make a one-page note: what changes after truncation and what remains equivalent. | I2: Start of Chapter 7 | O2: =IF(OR($K2="",$M2=""),"",IFERROR($K2+VLOOKUP($M2,'Redo Rules'!$A$2:$D$5,4,FALSE),""))
A3: 2 | B3: 46178 | C3: Read | D3: A. WLLN foundation | E3: 7.2 | F3: Read: General WLLN theorem. Write conditions (7.2)–(7.4) as a checklist: big jumps, truncated variance, centering. | I3: 7.1 read | O3: =IF(OR($K3="",$M3=""),"",IFERROR($K3+VLOOKUP($M3,'Redo Rules'!$A$2:$D$5,4,FALSE),""))
A4: 3 | B4: 46179 | C4: Exercise | D4: A. WLLN foundation | E4: 7.2 | F4: Do Exercise 2: sample variance consistency. | G4: 7.2 | H4: 7.2 General WLLN / Chebyshev logic | I4: Finish 7.1–7.2 reading | K4: 46176 | L4: 46178 | M4: Crack it | O4: =IF(OR($K4="",$M4=""),"",IFERROR($K4+VLOOKUP($M4,'Redo Rules'!$A$2:$D$5,4,FALSE),"")) -> 46178 | P4: Complete
A5: 4 | B5: 46180 | C5: Exercise | D5: A. WLLN foundation | E5: 7.2 | F5: Do Exercise 3: occupancy problem. | G5: 7.3 | H5: 7.2 WLLN / variance computation | I5: Exercise 2 attempted | K5: 46177 | M5: Skeleton | O5: =IF(OR($K5="",$M5=""),"",IFERROR($K5+VLOOKUP($M5,'Redo Rules'!$A$2:$D$5,4,FALSE),"")) -> 46179
A6: 5 | B6: 46181 | C6: Exercise | D6: A. WLLN foundation | E6: 7.2 | F6: Do Exercise 4: Monte Carlo integration interpretation. | G6: 7.4 | H6: 7.2 WLLN + Chapter 5 integration | I6: Exercise 3 attempted | K6: 46178 | M6: Crack it | O6: =IF(OR($K6="",$M6=""),"",IFERROR($K6+VLOOKUP($M6,'Redo Rules'!$A$2:$D$5,4,FALSE),"")) -> 46180
A7: 6 | B7: 46182 | C7: Exercise | D7: A. WLLN applications | E7: 7.2 | F7: Do Exercise 21: exponential/gamma approximation using WLLN. | G7: 7.21 | H7: 7.2 WLLN | I7: Exercise 4 attempted | O7: =IF(OR($K7="",$M7=""),"",IFERROR($K7+VLOOKUP($M7,'Redo Rules'!$A$2:$D$5,4,FALSE),""))
A8: 7 | B8: 46183 | C8: Exercise | D8: A. WLLN applications | E8: 7.2 | F8: Do Exercise 22: WLLN and inversion of Laplace transforms. | G8: 7.22 | H8: 7.2 WLLN | I8: Exercise 21 attempted | O8: =IF(OR($K8="",$M8=""),"",IFERROR($K8+VLOOKUP($M8,'Redo Rules'!$A$2:$D$5,4,FALSE),""))
A9: 8 | B9: 46184 | C9: Exercise | D9: A. WLLN applications | E9: 7.2 | F9: Do Exercise 23: cube approximated by annulus. | G9: 7.23 | H9: 7.2 WLLN / iid uniform | I9: Exercise 22 attempted | O9: =IF(OR($K9="",$M9=""),"",IFERROR($K9+VLOOKUP($M9,'Redo Rules'!$A$2:$D$5,4,FALSE),""))
A10: 9 | B10: 46185 | C10: Exercise | D10: A. WLLN applications | E10: 7.2 | F10: Do Exercise 27: further WLLN applications. | G10: 7.27 | H10: 7.2 WLLN | I10: Exercise 23 attempted | O10: =IF(OR($K10="",$M10=""),"",IFERROR($K10+VLOOKUP($M10,'Redo Rules'!$A$2:$D$5,4,FALSE),""))
A11: 10 | B11: 46186 | C11: Exercise | D11: A. WLLN applications | E11: 7.2 | F11: Do Exercise 28: uncorrelated WLLN. | G11: 7.28 | H11: 7.2 WLLN / L2 convergence | I11: Exercise 27 attempted | O11: =IF(OR($K11="",$M11=""),"",IFERROR($K11+VLOOKUP($M11,'Redo Rules'!$A$2:$D$5,4,FALSE),""))
A12: 11 | B12: 46187 | C12: Gate | D12: A. WLLN foundation | E12: 7.1–7.2 | F12: Proceed gate: can you state the WLLN checklist without looking? If not, redo reading notes before Block B. | H12: Gate before 7.3 | I12: Exercises 2,3,4,21,22,23,27,28 attempted | J12: Proceed only if reading notes + at least first attempts are done | O12: =IF(OR($K12="",$M12=""),"",IFERROR($K12+VLOOKUP($M12,'Redo Rules'!$A$2:$D$5,4,FALSE),""))
A13: 12 | B13: 46188 | C13: Read | D13: B. a.s. convergence of sums | E13: 7.3 | F13: Read: Skorohod inequality, Kolmogorov convergence criterion, and tail/convergence logic. | I13: Block A gate passed | O13: =IF(OR($K13="",$M13=""),"",IFERROR($K13+VLOOKUP($M13,'Redo Rules'!$A$2:$D$5,4,FALSE),""))
A14: 13 | B14: 46189 | C14: Exercise | D14: B. a.s. convergence of sums | E14: 7.3 | F14: Do Exercise 1: random signs and convergence of series. | G14: 7.1 | H14: 7.3 series convergence / later 7.6 check | I14: 7.3 read | O14: =IF(OR($K14="",$M14=""),"",IFERROR($K14+VLOOKUP($M14,'Redo Rules'!$A$2:$D$5,4,FALSE),""))
A15: 14 | B15: 46190 | C15: Exercise | D15: B. a.s. convergence of sums | E15: 7.3 | F15: Do Exercise 5: L2 convergence and random signs. | G15: 7.5 | H15: 7.3 convergence criterion | I15: Exercise 1 attempted | O15: =IF(OR($K15="",$M15=""),"",IFERROR($K15+VLOOKUP($M15,'Redo Rules'!$A$2:$D$5,4,FALSE),""))
A16: 15 | B16: 46191 | C16: Exercise | D16: B. a.s. convergence of sums | E16: 7.3 | F16: Do Exercise 7: partial converse to Borel-Cantelli. | G16: 7.7 | H16: 7.3 a.s. tools + Borel-Cantelli | I16: Exercise 5 attempted | O16: =IF(OR($K16="",$M16=""),"",IFERROR($K16+VLOOKUP($M16,'Redo Rules'!$A$2:$D$5,4,FALSE),""))
A17: 16 | B17: 46192 | C17: Exercise | D17: B. a.s. convergence of sums | E17: 7.3 | F17: Do Exercise 34: normal sine series convergence. | G17: 7.34 | H17: 7.3 Kolmogorov convergence criterion | I17: Exercise 7 attempted | O17: =IF(OR($K17="",$M17=""),"",IFERROR($K17+VLOOKUP($M17,'Redo Rules'!$A$2:$D$5,4,FALSE),""))
A18: 17 | B18: 46193 | C18: Exercise | D18: B. a.s. convergence of sums | E18: 7.3 | F18: Do Exercise 38: Cantor distribution series. | G18: 7.38 | H18: 7.3 almost sure convergence of series | I18: Exercise 34 attempted | O18: =IF(OR($K18="",$M18=""),"",IFERROR($K18+VLOOKUP($M18,'Redo Rules'!$A$2:$D$5,4,FALSE),""))
A19: 18 | B19: 46194 | C19: Exercise | D19: B. a.s. convergence of sums | E19: 7.3 | F19: Do Exercise 41: bounded differences and variance condition. | G19: 7.41 | H19: 7.3 convergence criterion | I19: Exercise 38 attempted | O19: =IF(OR($K19="",$M19=""),"",IFERROR($K19+VLOOKUP($M19,'Redo Rules'!$A$2:$D$5,4,FALSE),""))
A20: 19 | B20: 46195 | C20: Exercise | D20: B. a.s. convergence of sums | E20: 7.3 | F20: Do Exercise 42: convergence from summable variances. | G20: 7.42 | H20: 7.3 variance + Borel-Cantelli | I20: Exercise 41 attempted | O20: =IF(OR($K20="",$M20=""),"",IFERROR($K20+VLOOKUP($M20,'Redo Rules'!$A$2:$D$5,4,FALSE),""))
A21: 20 | B21: 46196 | C21: Gate | D21: B. a.s. convergence of sums | E21: 7.3 | F21: Proceed gate: distinguish convergence of a series from convergence of averages. Record which theorem you used for each exercise. | H21: Gate before SLLN | I21: Block B exercises attempted | J21: Proceed only if theorem usage is explicit | O21: =IF(OR($K21="",$M21=""),"",IFERROR($K21+VLOOKUP($M21,'Redo Rules'!$A$2:$D$5,4,FALSE),""))
A22: 21 | B22: 46197 | C22: Read | D22: C. SLLN mechanism | E22: 7.4 | F22: Read: Kronecker lemma and the strong law route from convergence of weighted series to normalized sums. | I22: Block B gate passed | O22: =IF(OR($K22="",$M22=""),"",IFERROR($K22+VLOOKUP($M22,'Redo Rules'!$A$2:$D$5,4,FALSE),""))
A23: 22 | B23: 46198 | C23: Read | D23: C. SLLN mechanism | E23: 7.4.1 | F23: Read: two examples. Record how record counts and pure birth process use the preceding machinery. | I23: 7.4 read | O23: =IF(OR($K23="",$M23=""),"",IFERROR($K23+VLOOKUP($M23,'Redo Rules'!$A$2:$D$5,4,FALSE),""))
A24: 23 | B24: 46199 | C24: Exercise | D24: C. SLLN mechanism | E24: 7.4 | F24: Do Exercise 18: stronger normalization with sqrt(n) log n. | G24: 7.18 | H24: 7.4 Kronecker / convergence criterion | I24: 7.4 read | O24: =IF(OR($K24="",$M24=""),"",IFERROR($K24+VLOOKUP($M24,'Redo Rules'!$A$2:$D$5,4,FALSE),""))
A25: 24 | B25: 46200 | C25: Exercise | D25: C. SLLN mechanism | E25: 7.4 | F25: Do Exercise 31: Poisson sums normalized by expectation. | G25: 7.31 | H25: 7.4 SLLN for independent non-iid | I25: Exercise 18 attempted | O25: =IF(OR($K25="",$M25=""),"",IFERROR($K25+VLOOKUP($M25,'Redo Rules'!$A$2:$D$5,4,FALSE),""))
A26: 25 | B26: 46201 | C26: Exercise | D26: C. SLLN mechanism | E26: 7.4 | F26: Do Exercise 32: max of exponentials over log n. | G26: 7.32 | H26: 7.4 examples + Borel-Cantelli | I26: Exercise 31 attempted | O26: =IF(OR($K26="",$M26=""),"",IFERROR($K26+VLOOKUP($M26,'Redo Rules'!$A$2:$D$5,4,FALSE),""))
A27: 26 | B27: 46202 | C27: Exercise | D27: C. SLLN mechanism | E27: 7.4 | F27: Do Exercise 40: a.s. convergence criterion via probability and dyadic subsequence. | G27: 7.40 | H27: 7.4 a.s. vs i.p. bridge | I27: Exercise 32 attempted | O27: =IF(OR($K27="",$M27=""),"",IFERROR($K27+VLOOKUP($M27,'Redo Rules'!$A$2:$D$5,4,FALSE),""))
A28: 27 | B28: 46203 | C28: Gate | D28: C. SLLN mechanism | E28: 7.4 | F28: Proceed gate: can you explain why Kronecker lemma is not just algebra but a device for SLLN? | H28: Gate before iid SLLN | I28: Block C exercises attempted | J28: Proceed only if Kronecker role is clear | O28: =IF(OR($K28="",$M28=""),"",IFERROR($K28+VLOOKUP($M28,'Redo Rules'!$A$2:$D$5,4,FALSE),""))
A29: 28 | B29: 46204 | C29: Read | D29: D. iid SLLN and applications | E29: 7.5 | F29: Read: SLLN for iid sequences. Make an assumptions map: iid + integrability -> a.s. average convergence. | I29: Block C gate passed | O29: =IF(OR($K29="",$M29=""),"",IFERROR($K29+VLOOKUP($M29,'Redo Rules'!$A$2:$D$5,4,FALSE),""))
A30: 29 | B30: 46205 | C30: Read | D30: D. iid SLLN and applications | E30: 7.5.1 | F30: Read: applications of SLLN. Separate 'proof pattern' from 'application interpretation'. | I30: 7.5 read | O30: =IF(OR($K30="",$M30=""),"",IFERROR($K30+VLOOKUP($M30,'Redo Rules'!$A$2:$D$5,4,FALSE),""))
A31: 30 | B31: 46206 | C31: Exercise | D31: D. iid SLLN and applications | E31: 7.5–7.5.1 | F31: Do Exercise 8: SLLN plus L1 convergence via uniform integrability. | G31: 7.8 | H31: 7.5 SLLN + Chapter 6 UI | I31: 7.5–7.5.1 read or previous listed exercise attempted | O31: =IF(OR($K31="",$M31=""),"",IFERROR($K31+VLOOKUP($M31,'Redo Rules'!$A$2:$D$5,4,FALSE),""))
A32: 31 | B32: 46207 | C32: Exercise | D32: D. iid SLLN and applications | E32: 7.5–7.5.1 | F32: Do Exercise 9: bounded coefficient weighted average. | G32: 7.9 | H32: 7.5 proof of SLLN | I32: 7.5–7.5.1 read or previous listed exercise attempted | O32: =IF(OR($K32="",$M32=""),"",IFERROR($K32+VLOOKUP($M32,'Redo Rules'!$A$2:$D$5,4,FALSE),""))
A33: 32 | B33: 46208 | C33: Exercise | D33: D. iid SLLN and applications | E33: 7.5–7.5.1 | F33: Do Exercise 10: m-dependent sequence and block frequencies. | G33: 7.10 | H33: 7.5 applications | I33: 7.5–7.5.1 read or previous listed exercise attempted | O33: =IF(OR($K33="",$M33=""),"",IFERROR($K33+VLOOKUP($M33,'Redo Rules'!$A$2:$D$5,4,FALSE),""))
A34: 33 | B34: 46209 | C34: Exercise | D34: D. iid SLLN and applications | E34: 7.5–7.5.1 | F34: Do Exercise 12: iterative uniforms and log limit. | G34: 7.12 | H34: 7.5 SLLN transformation | I34: 7.5–7.5.1 read or previous listed exercise attempted | O34: =IF(OR($K34="",$M34=""),"",IFERROR($K34+VLOOKUP($M34,'Redo Rules'!$A$2:$D$5,4,FALSE),""))
A35: 34 | B35: 46210 | C35: Exercise | D35: D. iid SLLN and applications | E35: 7.5–7.5.1 | F35: Do Exercise 16: maximum term over sum with nonzero mean. | G35: 7.16 | H35: 7.5 SLLN | I35: 7.5–7.5.1 read or previous listed exercise attempted | O35: =IF(OR($K35="",$M35=""),"",IFERROR($K35+VLOOKUP($M35,'Redo Rules'!$A$2:$D$5,4,FALSE),""))
A36: 35 | B36: 46211 | C36: Exercise | D36: D. iid SLLN and applications | E36: 7.5–7.5.1 | F36: Do Exercise 35: one-sided infinite mean and truncation. | G36: 7.35 | H36: 7.5 SLLN + truncation | I36: 7.5–7.5.1 read or previous listed exercise attempted | O36: =IF(OR($K36="",$M36=""),"",IFERROR($K36+VLOOKUP($M36,'Redo Rules'!$A$2:$D$5,4,FALSE),""))
A37: 36 | B37: 46212 | C37: Exercise | D37: D. iid SLLN and applications | E37: 7.5–7.5.1 | F37: Do Exercise 39: independent indicators WLLN. | G37: 7.39 | H37: 7.5 SLLN / WLLN | I37: 7.5–7.5.1 read or previous listed exercise attempted | O37: =IF(OR($K37="",$M37=""),"",IFERROR($K37+VLOOKUP($M37,'Redo Rules'!$A$2:$D$5,4,FALSE),""))
A38: 37 | B38: 46213 | C38: Exercise | D38: D. iid SLLN and applications | E38: 7.5–7.5.1 | F38: Do Exercise 43: Bernoulli expansion distributions and singularity. | G38: 7.43 | H38: 7.5 SLLN | I38: 7.5–7.5.1 read or previous listed exercise attempted | O38: =IF(OR($K38="",$M38=""),"",IFERROR($K38+VLOOKUP($M38,'Redo Rules'!$A$2:$D$5,4,FALSE),""))
A39: 38 | B39: 46214 | C39: Exercise | D39: D. iid SLLN and applications | E39: 7.5–7.5.1 | F39: Do Exercise 44: likelihood ratio product. | G39: 7.44 | H39: 7.5 SLLN on log likelihood ratio | I39: 7.5–7.5.1 read or previous listed exercise attempted | O39: =IF(OR($K39="",$M39=""),"",IFERROR($K39+VLOOKUP($M39,'Redo Rules'!$A$2:$D$5,4,FALSE),""))
A40: 39 | B40: 46215 | C40: Exercise | D40: D. iid SLLN and applications | E40: 7.5–7.5.1 | F40: Do Exercise 45: entropy from matching probability. | G40: 7.45 | H40: 7.5 SLLN / information interpretation | I40: 7.5–7.5.1 read or previous listed exercise attempted | O40: =IF(OR($K40="",$M40=""),"",IFERROR($K40+VLOOKUP($M40,'Redo Rules'!$A$2:$D$5,4,FALSE),""))
...

Sheet Dashboard
A1: Resnick Chapter 7 Schedule
A2: Instruction | B2: Fill Actual Start for each row. For exercise rows, Actual Start is also the first attempt date. Suggested Redo Date is automatic.
A4: Total tasks | B4: =COUNTA('Master Schedule'!$A$2:$A$64) -> 63
A5: Reading rows | B5: =COUNTIF('Master Schedule'!$C$2:$C$64,"Read") -> 10
A6: Exercise rows | B6: =COUNTIF('Master Schedule'!$C$2:$C$64,"Exercise") -> 46
A7: Gate rows | B7: =COUNTIF('Master Schedule'!$C$2:$C$64,"Gate") -> 5
A8: Summary rows | B8: =COUNTIF('Master Schedule'!$C$2:$C$64,"Summary") -> 2
A9: Rows completed | B9: =COUNTIF('Master Schedule'!$L$2:$L$64,"<>") -> 1
A10: Redo due or overdue | B10: =COUNTIFS('Master Schedule'!$O$2:$O$64,"<="&TODAY(),'Master Schedule'!$O$2:$O$64,">0",'Master Schedule'!$P$2:$P$64,"") -> 0
A12: Totally ignorance | B12: =COUNTIF('Master Schedule'!$M$2:$M$64,"Totally ignorance") -> 0
A13: Spark | B13: =COUNTIF('Master Schedule'!$M$2:$M$64,"Spark") -> 0
A14: Skeleton | B14: =COUNTIF('Master Schedule'!$M$2:$M$64,"Skeleton") -> 1
A15: Crack it | B15: =COUNTIF('Master Schedule'!$M$2:$M$64,"Crack it") -> 2
A17: Main fill-out columns | B17: K:R in Master Schedule
A18: Redo formula source | B18: Actual Start + First-pass Status

Sheet Redo Rules
A1: First-pass Status | B1: Meaning | C1: Recommended Action | D1: Redo Offset Days
A2: Totally ignorance | B2: Cannot write meaningful structure. | C2: Redo next day after rereading the exact theorem/definition; ask for minimum hint only if still blank. | D2: 1
A3: Spark | B3: Blur picture appears but needs ignition. | C3: Redo after two days with one minimum hint. | D3: 2
A4: Skeleton | B4: Direction is right but missing the logical bridge. | C4: Redo after two days; focus only on the missing bridge. | D4: 2
A5: Crack it | B5: Logic basically correct. | C5: C1 after two days; no immediate redo unless proof was messy. | D5: 2
A6: Note | B6: Actual Start is also the first attempt date for exercise rows. | C6: Suggested Redo Date = Actual Start + offset based on First-pass Status.
